<?xml version="1.0"?>
<robot name="acrome_mini_robot" xmlns:xacro="http://www.ros.org/wiki/xacro">
  <!-- #############################################
       Minimal differential-drive URDF using STL meshes
       Paths are absolute as provided by you. Adjust joint/origin xyz
       values if the wheels do not align perfectly with the base mesh.
       REP-103 frames: +X forward, +Y left, +Z up.
       ############################################# -->

  <!-- ================= Base Link ================= -->
  <link name="base_link">
    <inertial>
      <!-- Placeholder inertia; replace with measured values if available -->
      <origin xyz="0 0 0" rpy="0 0 0"/>
      <mass value="2.0"/>
      <inertia ixx="0.02" ixy="0.0" ixz="0.0" iyy="0.03" iyz="0.0" izz="0.03"/>
    </inertial>

    <visual>
      <!-- If the model looks flipped, try rpy="0 0 3.14159" -->
      <origin xyz="0 0 0" rpy="0 0 0"/>
      <geometry>
        <mesh filename="package://set_slam/meshes/base_link.stl" scale="1 1 1"/>
      </geometry>
      <material name="base_grey">
        <color rgba="0.6 0.6 0.6 1.0"/>
      </material>
    </visual>

    <collision>
      <origin xyz="0 0 0" rpy="0 0 0"/>
      <geometry>
        <mesh filename="package://set_slam/meshes/base_link.stl" scale="1 1 1"/>
      </geometry>
    </collision>
  </link>

  <!-- A flat frame on the ground projection of base_link (handy for navigation) -->
  <link name="base_footprint"/>
  <joint name="base_footprint_joint" type="fixed">
    <parent link="base_footprint"/>
    <child link="base_link"/>
    <!-- Set z so base_footprint sits on the ground if your base_link z-origin is above ground -->
    <origin xyz="0 0 0" rpy="0 0 0"/>
  </joint>

  <!-- ================ Left Wheel ================ -->
  <link name="left_wheel_link">
    <inertial>
      <origin xyz="0 0 0" rpy="0 0 0"/>
      <mass value="0.25"/>
      <inertia ixx="0.0005" ixy="0.0" ixz="0.0" iyy="0.0007" iyz="0.0" izz="0.0005"/>
    </inertial>

    <visual>
      <origin xyz="0 0 0" rpy="0 0 0"/>
      <geometry>
        <mesh filename="package://set_slam/meshes/left_wheel.stl" scale="1 1 1"/>
      </geometry>
      <material name="wheel_black">
        <color rgba="0.1 0.1 0.1 1.0"/>
      </material>
    </visual>

    <collision>
      <origin xyz="0 0 0" rpy="0 0 0"/>
      <geometry>
        <mesh filename="package://set_slam/meshes/left_wheel.stl" scale="1 1 1"/>
      </geometry>
    </collision>
  </link>

  <joint name="left_wheel_joint" type="continuous">
    <parent link="base_link"/>
    <child link="left_wheel_link"/>
    <!--
      The wheel rotates around its axle; with REP-103 this is +Y.
      Tune xyz to place the wheel correctly relative to the base mesh.
      Example values below assume ~0.18 m track width and ~0.04 m radius.
    -->
    <origin xyz="-0.14 0 -0.01" rpy="0 0 0"/>
    <axis xyz="0 1 0"/>
  </joint>

  <!-- ================ Right Wheel ================ -->
  <link name="right_wheel_link">
    <inertial>
      <origin xyz="0 0 0" rpy="0 0 0"/>
      <mass value="0.25"/>
      <inertia ixx="0.0005" ixy="0.0" ixz="0.0" iyy="0.0007" iyz="0.0" izz="0.0005"/>
    </inertial>

    <visual>
      <origin xyz="0 0 0" rpy="0 0 0"/>
      <geometry>
        <mesh filename="package://set_slam/meshes/right_wheel.stl" scale="1 1 1"/>
      </geometry>
      <material name="wheel_black"/>
    </visual>

    <collision>
      <origin xyz="0 0 0" rpy="0 0 0"/>
      <geometry>
        <mesh filename="package://set_slam/meshes/right_wheel.stl" scale="1 1 1"/>
      </geometry>
    </collision>
  </link>

  <joint name="right_wheel_joint" type="continuous">
    <parent link="base_link"/>
    <child link="right_wheel_link"/>
    <origin xyz="0.14 0 -0.01" rpy="0 0 0"/>
    <axis xyz="0 1 0"/>
  </joint>

  <!-- ================= Optional caster (placeholder) ================= -->
  <!-- If your robot has a caster, define it here and connect with a fixed joint. -->

  <link name="caster_link">
    <visual>
      <geometry>
        <cylinder radius="0.02" length="0.01"/>
      </geometry>
      <material name="caster_grey"><color rgba="0.5 0.5 0.5 1.0"/></material>
    </visual>
  </link>
  <joint name="caster_joint" type="fixed">
    <parent link="base_link"/>
    <child link="caster_link"/>
    <origin xyz="-0.08 0 -0.02" rpy="0 0 0"/>
  </joint>

  <!-- ================= Coordinate frames (visual aids) ================= -->
  <!-- Small axis markers to help verify orientation in RViz -->
  <link name="base_axis_vis">
    <visual>
      <origin xyz="0 0 0" rpy="0 0 0"/>
      <geometry>
        <box size="0.001 0.001 0.001"/>
      </geometry>
      <material name="transparent"><color rgba="0 0 0 0"/></material>
    </visual>
  </link>
  <joint name="base_axis_joint" type="fixed">
    <parent link="base_link"/>
    <child link="base_axis_vis"/>
    <origin xyz="0 0 0" rpy="0 0 0"/>
  </joint>

  <!-- ================= Notes =================
    * Tune the left/right wheel joint <origin> xyz until the wheels sit correctly in the model.
    * For simulation or control, add transmissions and gazebo_ros2_control plugins separately.
  ================= -->
</robot>
